Workbook

Sheet Fixtures
A1: Date | B1: Day | C1: Opposition | D1: Competition | E1: Home / Away | F1: Postponed | G1: Goals For | H1: Goals Against | I1: Result
A2: 46271 | B2: =Fixtures[[#This Row],[Date]] -> 46271 | C2: DAN | F2: FALSE | I2: {=IF(OR(Fixtures[[#This Row],[Goals For]]="",Fixtures[[#This Row],[Goals Against]]=""), IF(Fixtures[[#This Row],[Postponed]]=TRUE,"Postponed",""), _xlfn.IFS(Fixtures[[#This Row],[Goals For]]>Fixtures[[#This Row],[Goals Against]],"Win", Fixtures[[#This Row],[Goals For]]<Fixtures[[#This Row],[Goals Against]],"Lose", Fixtures[[#This Row],[Goals For]]=Fixtures[[#This Row],[Goals Against]],"Draw"))} | N2: H | O2: Home
A3: 46278 | B3: =Fixtures[[#This Row],[Date]] -> 46278 | F3: FALSE | I3: {=IF(OR(Fixtures[[#This Row],[Goals For]]="",Fixtures[[#This Row],[Goals Against]]=""), IF(Fixtures[[#This Row],[Postponed]]=TRUE,"Postponed",""), _xlfn.IFS(Fixtures[[#This Row],[Goals For]]>Fixtures[[#This Row],[Goals Against]],"Win", Fixtures[[#This Row],[Goals For]]<Fixtures[[#This Row],[Goals Against]],"Lose", Fixtures[[#This Row],[Goals For]]=Fixtures[[#This Row],[Goals Against]],"Draw"))} | N3: A | O3: Away
A4: 46285 | B4: =Fixtures[[#This Row],[Date]] -> 46285 | F4: FALSE | I4: {=IF(OR(Fixtures[[#This Row],[Goals For]]="",Fixtures[[#This Row],[Goals Against]]=""), IF(Fixtures[[#This Row],[Postponed]]=TRUE,"Postponed",""), _xlfn.IFS(Fixtures[[#This Row],[Goals For]]>Fixtures[[#This Row],[Goals Against]],"Win", Fixtures[[#This Row],[Goals For]]<Fixtures[[#This Row],[Goals Against]],"Lose", Fixtures[[#This Row],[Goals For]]=Fixtures[[#This Row],[Goals Against]],"Draw"))} | N4: F | O4: Friendly
A5: 46292 | B5: =Fixtures[[#This Row],[Date]] -> 46292 | F5: FALSE | I5: {=IF(OR(Fixtures[[#This Row],[Goals For]]="",Fixtures[[#This Row],[Goals Against]]=""), IF(Fixtures[[#This Row],[Postponed]]=TRUE,"Postponed",""), _xlfn.IFS(Fixtures[[#This Row],[Goals For]]>Fixtures[[#This Row],[Goals Against]],"Win", Fixtures[[#This Row],[Goals For]]<Fixtures[[#This Row],[Goals Against]],"Lose", Fixtures[[#This Row],[Goals For]]=Fixtures[[#This Row],[Goals Against]],"Draw"))} | N5: L | O5: League
A6: 46299 | B6: =Fixtures[[#This Row],[Date]] -> 46299 | F6: FALSE | I6: {=IF(OR(Fixtures[[#This Row],[Goals For]]="",Fixtures[[#This Row],[Goals Against]]=""), IF(Fixtures[[#This Row],[Postponed]]=TRUE,"Postponed",""), _xlfn.IFS(Fixtures[[#This Row],[Goals For]]>Fixtures[[#This Row],[Goals Against]],"Win", Fixtures[[#This Row],[Goals For]]<Fixtures[[#This Row],[Goals Against]],"Lose", Fixtures[[#This Row],[Goals For]]=Fixtures[[#This Row],[Goals Against]],"Draw"))} | N6: C | O6: Cup
A7: 46306 | B7: =Fixtures[[#This Row],[Date]] -> 46306 | F7: FALSE | I7: {=IF(OR(Fixtures[[#This Row],[Goals For]]="",Fixtures[[#This Row],[Goals Against]]=""), IF(Fixtures[[#This Row],[Postponed]]=TRUE,"Postponed",""), _xlfn.IFS(Fixtures[[#This Row],[Goals For]]>Fixtures[[#This Row],[Goals Against]],"Win", Fixtures[[#This Row],[Goals For]]<Fixtures[[#This Row],[Goals Against]],"Lose", Fixtures[[#This Row],[Goals For]]=Fixtures[[#This Row],[Goals Against]],"Draw"))} | N7: S | O7: Shield
A8: 46313 | B8: =Fixtures[[#This Row],[Date]] -> 46313 | F8: FALSE | I8: {=IF(OR(Fixtures[[#This Row],[Goals For]]="",Fixtures[[#This Row],[Goals Against]]=""), IF(Fixtures[[#This Row],[Postponed]]=TRUE,"Postponed",""), _xlfn.IFS(Fixtures[[#This Row],[Goals For]]>Fixtures[[#This Row],[Goals Against]],"Win", Fixtures[[#This Row],[Goals For]]<Fixtures[[#This Row],[Goals Against]],"Lose", Fixtures[[#This Row],[Goals For]]=Fixtures[[#This Row],[Goals Against]],"Draw"))}
A9: 46320 | B9: =Fixtures[[#This Row],[Date]] -> 46320 | F9: FALSE | I9: {=IF(OR(Fixtures[[#This Row],[Goals For]]="",Fixtures[[#This Row],[Goals Against]]=""), IF(Fixtures[[#This Row],[Postponed]]=TRUE,"Postponed",""), _xlfn.IFS(Fixtures[[#This Row],[Goals For]]>Fixtures[[#This Row],[Goals Against]],"Win", Fixtures[[#This Row],[Goals For]]<Fixtures[[#This Row],[Goals Against]],"Lose", Fixtures[[#This Row],[Goals For]]=Fixtures[[#This Row],[Goals Against]],"Draw"))}
A10: 46327 | B10: =Fixtures[[#This Row],[Date]] -> 46327 | F10: FALSE | I10: {=IF(OR(Fixtures[[#This Row],[Goals For]]="",Fixtures[[#This Row],[Goals Against]]=""), IF(Fixtures[[#This Row],[Postponed]]=TRUE,"Postponed",""), _xlfn.IFS(Fixtures[[#This Row],[Goals For]]>Fixtures[[#This Row],[Goals Against]],"Win", Fixtures[[#This Row],[Goals For]]<Fixtures[[#This Row],[Goals Against]],"Lose", Fixtures[[#This Row],[Goals For]]=Fixtures[[#This Row],[Goals Against]],"Draw"))} | N10: https://fulltime.thefa.com/index.html?league=3117271
A11: 46334 | B11: =Fixtures[[#This Row],[Date]] -> 46334 | F11: FALSE | I11: {=IF(OR(Fixtures[[#This Row],[Goals For]]="",Fixtures[[#This Row],[Goals Against]]=""), IF(Fixtures[[#This Row],[Postponed]]=TRUE,"Postponed",""), _xlfn.IFS(Fixtures[[#This Row],[Goals For]]>Fixtures[[#This Row],[Goals Against]],"Win", Fixtures[[#This Row],[Goals For]]<Fixtures[[#This Row],[Goals Against]],"Lose", Fixtures[[#This Row],[Goals For]]=Fixtures[[#This Row],[Goals Against]],"Draw"))}
A12: 46341 | B12: =Fixtures[[#This Row],[Date]] -> 46341 | F12: FALSE | I12: {=IF(OR(Fixtures[[#This Row],[Goals For]]="",Fixtures[[#This Row],[Goals Against]]=""), IF(Fixtures[[#This Row],[Postponed]]=TRUE,"Postponed",""), _xlfn.IFS(Fixtures[[#This Row],[Goals For]]>Fixtures[[#This Row],[Goals Against]],"Win", Fixtures[[#This Row],[Goals For]]<Fixtures[[#This Row],[Goals Against]],"Lose", Fixtures[[#This Row],[Goals For]]=Fixtures[[#This Row],[Goals Against]],"Draw"))} | N12: https://fulltime.thefa.com/table.html?divisionseason=890410319#tab-1
A13: 46348 | B13: =Fixtures[[#This Row],[Date]] -> 46348 | F13: FALSE | I13: {=IF(OR(Fixtures[[#This Row],[Goals For]]="",Fixtures[[#This Row],[Goals Against]]=""), IF(Fixtures[[#This Row],[Postponed]]=TRUE,"Postponed",""), _xlfn.IFS(Fixtures[[#This Row],[Goals For]]>Fixtures[[#This Row],[Goals Against]],"Win", Fixtures[[#This Row],[Goals For]]<Fixtures[[#This Row],[Goals Against]],"Lose", Fixtures[[#This Row],[Goals For]]=Fixtures[[#This Row],[Goals Against]],"Draw"))}
A14: 46355 | B14: =Fixtures[[#This Row],[Date]] -> 46355 | F14: FALSE | I14: {=IF(OR(Fixtures[[#This Row],[Goals For]]="",Fixtures[[#This Row],[Goals Against]]=""), IF(Fixtures[[#This Row],[Postponed]]=TRUE,"Postponed",""), _xlfn.IFS(Fixtures[[#This Row],[Goals For]]>Fixtures[[#This Row],[Goals Against]],"Win", Fixtures[[#This Row],[Goals For]]<Fixtures[[#This Row],[Goals Against]],"Lose", Fixtures[[#This Row],[Goals For]]=Fixtures[[#This Row],[Goals Against]],"Draw"))}
A15: 46362 | B15: =Fixtures[[#This Row],[Date]] -> 46362 | F15: FALSE | I15: {=IF(OR(Fixtures[[#This Row],[Goals For]]="",Fixtures[[#This Row],[Goals Against]]=""), IF(Fixtures[[#This Row],[Postponed]]=TRUE,"Postponed",""), _xlfn.IFS(Fixtures[[#This Row],[Goals For]]>Fixtures[[#This Row],[Goals Against]],"Win", Fixtures[[#This Row],[Goals For]]<Fixtures[[#This Row],[Goals Against]],"Lose", Fixtures[[#This Row],[Goals For]]=Fixtures[[#This Row],[Goals Against]],"Draw"))}
A16: 46369 | B16: =Fixtures[[#This Row],[Date]] -> 46369 | F16: FALSE | I16: {=IF(OR(Fixtures[[#This Row],[Goals For]]="",Fixtures[[#This Row],[Goals Against]]=""), IF(Fixtures[[#This Row],[Postponed]]=TRUE,"Postponed",""), _xlfn.IFS(Fixtures[[#This Row],[Goals For]]>Fixtures[[#This Row],[Goals Against]],"Win", Fixtures[[#This Row],[Goals For]]<Fixtures[[#This Row],[Goals Against]],"Lose", Fixtures[[#This Row],[Goals For]]=Fixtures[[#This Row],[Goals Against]],"Draw"))}
A17: 46376 | B17: =Fixtures[[#This Row],[Date]] -> 46376 | F17: FALSE | I17: {=IF(OR(Fixtures[[#This Row],[Goals For]]="",Fixtures[[#This Row],[Goals Against]]=""), IF(Fixtures[[#This Row],[Postponed]]=TRUE,"Postponed",""), _xlfn.IFS(Fixtures[[#This Row],[Goals For]]>Fixtures[[#This Row],[Goals Against]],"Win", Fixtures[[#This Row],[Goals For]]<Fixtures[[#This Row],[Goals Against]],"Lose", Fixtures[[#This Row],[Goals For]]=Fixtures[[#This Row],[Goals Against]],"Draw"))}
A18: 46383 | B18: =Fixtures[[#This Row],[Date]] -> 46383 | F18: FALSE | I18: {=IF(OR(Fixtures[[#This Row],[Goals For]]="",Fixtures[[#This Row],[Goals Against]]=""), IF(Fixtures[[#This Row],[Postponed]]=TRUE,"Postponed",""), _xlfn.IFS(Fixtures[[#This Row],[Goals For]]>Fixtures[[#This Row],[Goals Against]],"Win", Fixtures[[#This Row],[Goals For]]<Fixtures[[#This Row],[Goals Against]],"Lose", Fixtures[[#This Row],[Goals For]]=Fixtures[[#This Row],[Goals Against]],"Draw"))}
A19: 46390 | B19: =Fixtures[[#This Row],[Date]] -> 46390 | F19: FALSE | I19: {=IF(OR(Fixtures[[#This Row],[Goals For]]="",Fixtures[[#This Row],[Goals Against]]=""), IF(Fixtures[[#This Row],[Postponed]]=TRUE,"Postponed",""), _xlfn.IFS(Fixtures[[#This Row],[Goals For]]>Fixtures[[#This Row],[Goals Against]],"Win", Fixtures[[#This Row],[Goals For]]<Fixtures[[#This Row],[Goals Against]],"Lose", Fixtures[[#This Row],[Goals For]]=Fixtures[[#This Row],[Goals Against]],"Draw"))}
A20: 46397 | B20: =Fixtures[[#This Row],[Date]] -> 46397 | F20: FALSE | I20: {=IF(OR(Fixtures[[#This Row],[Goals For]]="",Fixtures[[#This Row],[Goals Against]]=""), IF(Fixtures[[#This Row],[Postponed]]=TRUE,"Postponed",""), _xlfn.IFS(Fixtures[[#This Row],[Goals For]]>Fixtures[[#This Row],[Goals Against]],"Win", Fixtures[[#This Row],[Goals For]]<Fixtures[[#This Row],[Goals Against]],"Lose", Fixtures[[#This Row],[Goals For]]=Fixtures[[#This Row],[Goals Against]],"Draw"))}
A21: 46404 | B21: =Fixtures[[#This Row],[Date]] -> 46404 | F21: FALSE | I21: {=IF(OR(Fixtures[[#This Row],[Goals For]]="",Fixtures[[#This Row],[Goals Against]]=""), IF(Fixtures[[#This Row],[Postponed]]=TRUE,"Postponed",""), _xlfn.IFS(Fixtures[[#This Row],[Goals For]]>Fixtures[[#This Row],[Goals Against]],"Win", Fixtures[[#This Row],[Goals For]]<Fixtures[[#This Row],[Goals Against]],"Lose", Fixtures[[#This Row],[Goals For]]=Fixtures[[#This Row],[Goals Against]],"Draw"))}
A22: 46411 | B22: =Fixtures[[#This Row],[Date]] -> 46411 | F22: FALSE | I22: {=IF(OR(Fixtures[[#This Row],[Goals For]]="",Fixtures[[#This Row],[Goals Against]]=""), IF(Fixtures[[#This Row],[Postponed]]=TRUE,"Postponed",""), _xlfn.IFS(Fixtures[[#This Row],[Goals For]]>Fixtures[[#This Row],[Goals Against]],"Win", Fixtures[[#This Row],[Goals For]]<Fixtures[[#This Row],[Goals Against]],"Lose", Fixtures[[#This Row],[Goals For]]=Fixtures[[#This Row],[Goals Against]],"Draw"))}
A23: 46418 | B23: =Fixtures[[#This Row],[Date]] -> 46418 | F23: FALSE | I23: {=IF(OR(Fixtures[[#This Row],[Goals For]]="",Fixtures[[#This Row],[Goals Against]]=""), IF(Fixtures[[#This Row],[Postponed]]=TRUE,"Postponed",""), _xlfn.IFS(Fixtures[[#This Row],[Goals For]]>Fixtures[[#This Row],[Goals Against]],"Win", Fixtures[[#This Row],[Goals For]]<Fixtures[[#This Row],[Goals Against]],"Lose", Fixtures[[#This Row],[Goals For]]=Fixtures[[#This Row],[Goals Against]],"Draw"))}
A24: 46425 | B24: =Fixtures[[#This Row],[Date]] -> 46425 | F24: FALSE | I24: {=IF(OR(Fixtures[[#This Row],[Goals For]]="",Fixtures[[#This Row],[Goals Against]]=""), IF(Fixtures[[#This Row],[Postponed]]=TRUE,"Postponed",""), _xlfn.IFS(Fixtures[[#This Row],[Goals For]]>Fixtures[[#This Row],[Goals Against]],"Win", Fixtures[[#This Row],[Goals For]]<Fixtures[[#This Row],[Goals Against]],"Lose", Fixtures[[#This Row],[Goals For]]=Fixtures[[#This Row],[Goals Against]],"Draw"))}
... A53: 46628 | B53: =Fixtures[[#This Row],[Date]] -> 46628 | F53: FALSE | I53: {=IF(OR(Fixtures[[#This Row],[Goals For]]="",Fixtures[[#This Row],[Goals Against]]=""), IF(Fixtures[[#This Row],[Postponed]]=TRUE,"Postponed",""), _xlfn.IFS(Fixtures[[#This Row],[Goals For]]>Fixtures[[#This Row],[Goals Against]],"Win", Fixtures[[#This Row],[Goals For]]<Fixtures[[#This Row],[Goals Against]],"Lose", Fixtures[[#This Row],[Goals For]]=Fixtures[[#This Row],[Goals Against]],"Draw"))}

Sheet Goals
A1: Date | B1: Opposition | C1: Alf M | D1: Alfie F | E1: Bailey | F1: Brad | G1: Callum | H1: Danny | I1: Ethan | J1: Freddie | K1: George | L1: Jamie | M1: Jay | N1: Joe | O1: Josh | P1: Jude | Q1: Kalan | R1: Kazeem | S1: Keiran D | T1: Keiran R | U1: Liam | V1: Louie | W1: Rocco | X1: Ronnie D | Y1: Ronnie T | Z1: Ryan | AA1: Ryeley | AB1: Will | AC1: count
A2: =Fixtures[[#This Row],[Date]] -> 46271 | B2: =Fixtures[[#This Row],[Opposition]] -> DAN | AC2: =SUM(Goals[[#This Row],[Alf M]:[Will]]) -> 0
A3: 46278 | B3: =Fixtures[[#This Row],[Opposition]] -> 0 | AC3: =SUM(Goals[[#This Row],[Alf M]:[Will]]) -> 0
A4: 46285 | B4: =Fixtures[[#This Row],[Opposition]] -> 0 | AC4: =SUM(Goals[[#This Row],[Alf M]:[Will]]) -> 0
A5: 46292 | B5: =Fixtures[[#This Row],[Opposition]] -> 0 | AC5: =SUM(Goals[[#This Row],[Alf M]:[Will]]) -> 0
A6: 46299 | B6: =Fixtures[[#This Row],[Opposition]] -> 0 | AC6: =SUM(Goals[[#This Row],[Alf M]:[Will]]) -> 0
A7: 46306 | B7: =Fixtures[[#This Row],[Opposition]] -> 0 | AC7: =SUM(Goals[[#This Row],[Alf M]:[Will]]) -> 0
A8: 46313 | B8: =Fixtures[[#This Row],[Opposition]] -> 0 | AC8: =SUM(Goals[[#This Row],[Alf M]:[Will]]) -> 0
A9: 46320 | B9: =Fixtures[[#This Row],[Opposition]] -> 0 | AC9: =SUM(Goals[[#This Row],[Alf M]:[Will]]) -> 0
A10: 46327 | B10: =Fixtures[[#This Row],[Opposition]] -> 0 | AC10: =SUM(Goals[[#This Row],[Alf M]:[Will]]) -> 0
A11: 46334 | B11: =Fixtures[[#This Row],[Opposition]] -> 0 | AC11: =SUM(Goals[[#This Row],[Alf M]:[Will]]) -> 0
A12: 46341 | B12: =Fixtures[[#This Row],[Opposition]] -> 0 | AC12: =SUM(Goals[[#This Row],[Alf M]:[Will]]) -> 0
A13: 46348 | B13: =Fixtures[[#This Row],[Opposition]] -> 0 | AC13: =SUM(Goals[[#This Row],[Alf M]:[Will]]) -> 0
A14: 46355 | B14: =Fixtures[[#This Row],[Opposition]] -> 0 | AC14: =SUM(Goals[[#This Row],[Alf M]:[Will]]) -> 0
... A53: 46628 | B53: =Fixtures[[#This Row],[Opposition]] -> 0 | AC53: =SUM(Goals[[#This Row],[Alf M]:[Will]]) -> 0
B54: Total | C54: =SUBTOTAL(109,Goals[Alf M]) -> 0 | D54: =SUBTOTAL(109,Goals[Alfie F]) -> 0 | E54: =SUBTOTAL(109,Goals[Bailey]) -> 0 | F54: =SUBTOTAL(109,Goals[Brad]) -> 0 | G54: =SUBTOTAL(109,Goals[Callum]) -> 0 | H54: =SUBTOTAL(109,Goals[Danny]) -> 0 | I54: =SUBTOTAL(109,Goals[Ethan]) -> 0 | J54: =SUBTOTAL(109,Goals[Freddie]) -> 0 | K54: =SUBTOTAL(109,Goals[George]) -> 0 | L54: =SUBTOTAL(109,Goals[Jamie]) -> 0 | M54: =SUBTOTAL(109,Goals[Jay]) -> 0 | N54: =SUBTOTAL(109,Goals[Joe]) -> 0 | O54: =SUBTOTAL(109,Goals[Josh]) -> 0 | P54: =SUBTOTAL(109,Goals[Jude]) -> 0 | Q54: =SUBTOTAL(109,Goals[Kalan]) -> 0 | R54: =SUBTOTAL(109,Goals[Kazeem]) -> 0 | S54: =SUBTOTAL(109,Goals[Keiran D]) -> 0 | T54: =SUBTOTAL(109,Goals[Keiran R]) -> 0 | U54: =SUBTOTAL(109,Goals[Liam]) -> 0 | V54: =SUBTOTAL(109,Goals[Louie]) -> 0 | W54: =SUBTOTAL(109,Goals[Rocco]) -> 0 | X54: =SUBTOTAL(109,Goals[Ronnie D]) -> 0 | Y54: =SUBTOTAL(109,Goals[Ronnie T]) -> 0 | Z54: =SUBTOTAL(109,Goals[Ryan]) -> 0 | AA54: =SUBTOTAL(109,Goals[Ryeley]) -> 0 | AB54: =SUBTOTAL(109,Goals[Will]) -> 0 | AC54: =SUBTOTAL(109,Goals[count]) -> 0

Sheet Assists
A1: Date | B1: Opposition | C1: Alf M | D1: Alfie F | E1: Bailey | F1: Brad | G1: Callum | H1: Danny | I1: Ethan | J1: Freddie | K1: George | L1: Jamie | M1: Jay | N1: Joe | O1: Josh | P1: Jude | Q1: Kalan | R1: Kazeem | S1: Keiran D | T1: Keiran R | U1: Liam | V1: Louie | W1: Rocco | X1: Ronnie D | Y1: Ronnie T | Z1: Ryan | AA1: Ryeley | AB1: Will | AC1: Count
A2: 46271 | B2: =Fixtures[[#This Row],[Opposition]] -> DAN | AC2: =SUM(Assists[[#This Row],[Alf M]:[Will]]) -> 0
A3: 46278 | B3: =Fixtures[[#This Row],[Opposition]] -> 0 | AC3: =SUM(Assists[[#This Row],[Alf M]:[Will]]) -> 0
A4: 46285 | B4: =Fixtures[[#This Row],[Opposition]] -> 0 | AC4: =SUM(Assists[[#This Row],[Alf M]:[Will]]) -> 0
A5: 46292 | B5: =Fixtures[[#This Row],[Opposition]] -> 0 | AC5: =SUM(Assists[[#This Row],[Alf M]:[Will]]) -> 0
A6: 46299 | B6: =Fixtures[[#This Row],[Opposition]] -> 0 | AC6: =SUM(Assists[[#This Row],[Alf M]:[Will]]) -> 0
A7: 46306 | B7: =Fixtures[[#This Row],[Opposition]] -> 0 | AC7: =SUM(Assists[[#This Row],[Alf M]:[Will]]) -> 0
A8: 46313 | B8: =Fixtures[[#This Row],[Opposition]] -> 0 | AC8: =SUM(Assists[[#This Row],[Alf M]:[Will]]) -> 0
A9: 46320 | B9: =Fixtures[[#This Row],[Opposition]] -> 0 | AC9: =SUM(Assists[[#This Row],[Alf M]:[Will]]) -> 0
A10: 46327 | B10: =Fixtures[[#This Row],[Opposition]] -> 0 | AC10: =SUM(Assists[[#This Row],[Alf M]:[Will]]) -> 0
A11: 46334 | B11: =Fixtures[[#This Row],[Opposition]] -> 0 | AC11: =SUM(Assists[[#This Row],[Alf M]:[Will]]) -> 0
A12: 46341 | B12: =Fixtures[[#This Row],[Opposition]] -> 0 | AC12: =SUM(Assists[[#This Row],[Alf M]:[Will]]) -> 0
A13: 46348 | B13: =Fixtures[[#This Row],[Opposition]] -> 0 | AC13: =SUM(Assists[[#This Row],[Alf M]:[Will]]) -> 0
... A53: 46628 | B53: =Fixtures[[#This Row],[Opposition]] -> 0 | AC53: =SUM(Assists[[#This Row],[Alf M]:[Will]]) -> 0
B54: Total | C54: =SUBTOTAL(109,Assists[Alf M]) -> 0 | D54: =SUBTOTAL(109,Assists[Alfie F]) -> 0 | E54: =SUBTOTAL(109,Assists[Bailey]) -> 0 | F54: =SUBTOTAL(109,Assists[Brad]) -> 0 | G54: =SUBTOTAL(109,Assists[Callum]) -> 0 | H54: =SUBTOTAL(109,Assists[Danny]) -> 0 | I54: =SUBTOTAL(109,Assists[Ethan]) -> 0 | J54: =SUBTOTAL(109,Assists[Freddie]) -> 0 | K54: =SUBTOTAL(109,Assists[George]) -> 0 | L54: =SUBTOTAL(109,Assists[Jamie]) -> 0 | M54: =SUBTOTAL(109,Assists[Jay]) -> 0 | N54: =SUBTOTAL(109,Assists[Joe]) -> 0 | O54: =SUBTOTAL(109,Assists[Josh]) -> 0 | P54: =SUBTOTAL(109,Assists[Jude]) -> 0 | Q54: =SUBTOTAL(109,Assists[Kalan]) -> 0 | R54: =SUBTOTAL(109,Assists[Kazeem]) -> 0 | S54: =SUBTOTAL(109,Assists[Keiran D]) -> 0 | T54: =SUBTOTAL(109,Assists[Keiran R]) -> 0 | U54: =SUBTOTAL(109,Assists[Liam]) -> 0 | Y54: =SUBTOTAL(109,Assists[Ronnie T]) -> 0 | AA54: =SUBTOTAL(109,Assists[Ryeley]) -> 0 | AB54: =SUBTOTAL(109,Assists[Will]) -> 0 | AC54: =SUBTOTAL(109,Assists[Count]) -> 0

Sheet Events
A1: Date | B1: Opposition | C1: Alf M | D1: Alfie F | E1: Bailey | F1: Brad | G1: Callum | H1: Danny | I1: Ethan | J1: Freddie | K1: George | L1: Jamie | M1: Jay | N1: Joe | O1: Josh | P1: Jude | Q1: Kalan | R1: Kazeem | S1: Keiran D | T1: Keiran R | U1: Liam | V1: Louie | W1: Rocco | X1: Ronnie D | Y1: Ronnie T | Z1: Ryan | AA1: Ryeley | AB1: Will
A2: 46271 | B2: =Fixtures[[#This Row],[Opposition]] -> DAN
A3: 46278 | B3: =Fixtures[[#This Row],[Opposition]] -> 0
A4: 46285 | B4: =Fixtures[[#This Row],[Opposition]] -> 0
A5: 46292 | B5: =Fixtures[[#This Row],[Opposition]] -> 0
A6: 46299 | B6: =Fixtures[[#This Row],[Opposition]] -> 0
A7: 46306 | B7: =Fixtures[[#This Row],[Opposition]] -> 0
A8: 46313 | B8: =Fixtures[[#This Row],[Opposition]] -> 0
A9: 46320 | B9: =Fixtures[[#This Row],[Opposition]] -> 0
A10: 46327 | B10: =Fixtures[[#This Row],[Opposition]] -> 0
A11: 46334 | B11: =Fixtures[[#This Row],[Opposition]] -> 0
A12: 46341 | B12: =Fixtures[[#This Row],[Opposition]] -> 0
A13: 46348 | B13: =Fixtures[[#This Row],[Opposition]] -> 0
... A53: 46628 | B53: =Fixtures[[#This Row],[Opposition]] -> 0

Sheet Match Attendance
A1: Date | B1: Day | C1: Opposition | D1: Alf M | E1: Alfie F | F1: Bailey | G1: Brad | H1: Callum | I1: Danny | J1: Ethan | K1: Freddie | L1: George | M1: Jamie | N1: Jay | O1: Joe | P1: Josh | Q1: Jude | R1: Kalan | S1: Kazeem | T1: Keiran D | U1: Keiran R | V1: Liam | W1: Louie | X1: Rocco | Y1: Ronnie D | Z1: Ronnie T | AA1: Ryan | AB1: Ryeley | AC1: Will | AD1: COUNT
A2: =Fixtures[[#This Row],[Date]] -> 46271 | B2: =Match_Attendance[[#This Row],[Date]] -> 46271 | C2: =Fixtures[[#This Row],[Opposition]] -> DAN | D2: FALSE | E2: FALSE | F2: FALSE | G2: FALSE | H2: FALSE | I2: FALSE | J2: FALSE | K2: FALSE | L2: FALSE | M2: FALSE | N2: FALSE | O2: FALSE | P2: FALSE | Q2: FALSE | R2: FALSE | S2: FALSE | T2: FALSE | U2: FALSE | V2: FALSE | W2: FALSE | X2: FALSE | Y2: FALSE | Z2: FALSE | AA2: FALSE | AB2: FALSE | AC2: FALSE | AD2: =COUNTIF(Match_Attendance[[#This Row],[Alf M]:[Ronnie D]],"Y") -> 0
A3: =Fixtures[[#This Row],[Date]] -> 46278 | B3: =Match_Attendance[[#This Row],[Date]] -> 46278 | C3: =Fixtures[[#This Row],[Opposition]] -> 0 | D3: FALSE | E3: FALSE | F3: FALSE | G3: FALSE | H3: FALSE | I3: FALSE | J3: FALSE | K3: FALSE | L3: FALSE | M3: FALSE | N3: FALSE | O3: FALSE | P3: FALSE | Q3: FALSE | R3: FALSE | S3: FALSE | T3: FALSE | U3: FALSE | V3: FALSE | W3: FALSE | X3: FALSE | Y3: FALSE | Z3: FALSE | AA3: FALSE | AB3: FALSE | AC3: FALSE | AD3: =COUNTIF(Match_Attendance[[#This Row],[Alf M]:[Ronnie D]],"Y") -> 0
A4: =Fixtures[[#This Row],[Date]] -> 46285 | B4: =Match_Attendance[[#This Row],[Date]] -> 46285 | C4: =Fixtures[[#This Row],[Opposition]] -> 0 | D4: FALSE | E4: FALSE | F4: FALSE | G4: FALSE | H4: FALSE | I4: FALSE | J4: FALSE | K4: FALSE | L4: FALSE | M4: FALSE | N4: FALSE | O4: FALSE | P4: FALSE | Q4: FALSE | R4: FALSE | S4: FALSE | T4: FALSE | U4: FALSE | V4: FALSE | W4: FALSE | X4: FALSE | Y4: FALSE | Z4: FALSE | AA4: FALSE | AB4: FALSE | AC4: FALSE | AD4: =COUNTIF(Match_Attendance[[#This Row],[Alf M]:[Ronnie D]],"Y") -> 0
A5: =Fixtures[[#This Row],[Date]] -> 46292 | B5: =Match_Attendance[[#This Row],[Date]] -> 46292 | C5: =Fixtures[[#This Row],[Opposition]] -> 0 | D5: FALSE | E5: FALSE | F5: FALSE | G5: FALSE | H5: FALSE | I5: FALSE | J5: FALSE | K5: FALSE | L5: FALSE | M5: FALSE | N5: FALSE | O5: FALSE | P5: FALSE | Q5: FALSE | R5: FALSE | S5: FALSE | T5: FALSE | U5: FALSE | V5: FALSE | W5: FALSE | X5: FALSE | Y5: FALSE | Z5: FALSE | AA5: FALSE | AB5: FALSE | AC5: FALSE | AD5: =COUNTIF(Match_Attendance[[#This Row],[Alf M]:[Ronnie D]],"Y") -> 0
A6: =Fixtures[[#This Row],[Date]] -> 46299 | B6: =Match_Attendance[[#This Row],[Date]] -> 46299 | C6: =Fixtures[[#This Row],[Opposition]] -> 0 | D6: FALSE | E6: FALSE | F6: FALSE | G6: FALSE | H6: FALSE | I6: FALSE | J6: FALSE | K6: FALSE | L6: FALSE | M6: FALSE | N6: FALSE | O6: FALSE | P6: FALSE | Q6: FALSE | R6: FALSE | S6: FALSE | T6: FALSE | U6: FALSE | V6: FALSE | W6: FALSE | X6: FALSE | Y6: FALSE | Z6: FALSE | AA6: FALSE | AB6: FALSE | AC6: FALSE | AD6: =COUNTIF(Match_Attendance[[#This Row],[Alf M]:[Ronnie D]],"Y") -> 0
A7: =Fixtures[[#This Row],[Date]] -> 46306 | B7: =Match_Attendance[[#This Row],[Date]] -> 46306 | C7: =Fixtures[[#This Row],[Opposition]] -> 0 | D7: FALSE | E7: FALSE | F7: FALSE | G7: FALSE | H7: FALSE | I7: FALSE | J7: FALSE | K7: FALSE | L7: FALSE | M7: FALSE | N7: FALSE | O7: FALSE | P7: FALSE | Q7: FALSE | R7: FALSE | S7: FALSE | T7: FALSE | U7: FALSE | V7: FALSE | W7: FALSE | X7: FALSE | Y7: FALSE | Z7: FALSE | AA7: FALSE | AB7: FALSE | AC7: FALSE | AD7: =COUNTIF(Match_Attendance[[#This Row],[Alf M]:[Ronnie D]],"Y") -> 0
A8: =Fixtures[[#This Row],[Date]] -> 46313 | B8: =Match_Attendance[[#This Row],[Date]] -> 46313 | C8: =Fixtures[[#This Row],[Opposition]] -> 0 | D8: FALSE | E8: FALSE | F8: FALSE | G8: FALSE | H8: FALSE | I8: FALSE | J8: FALSE | K8: FALSE | L8: FALSE | M8: FALSE | N8: FALSE | O8: FALSE | P8: FALSE | Q8: FALSE | R8: FALSE | S8: FALSE | T8: FALSE | U8: FALSE | V8: FALSE | W8: FALSE | X8: FALSE | Y8: FALSE | Z8: FALSE | AA8: FALSE | AB8: FALSE | AC8: FALSE | AD8: =COUNTIF(Match_Attendance[[#This Row],[Alf M]:[Ronnie D]],"Y") -> 0
A9: =Fixtures[[#This Row],[Date]] -> 46320 | B9: =Match_Attendance[[#This Row],[Date]] -> 46320 | C9: =Fixtures[[#This Row],[Opposition]] -> 0 | D9: FALSE | E9: FALSE | F9: FALSE | G9: FALSE | H9: FALSE | I9: FALSE | J9: FALSE | K9: FALSE | L9: FALSE | M9: FALSE | N9: FALSE | O9: FALSE | P9: FALSE | Q9: FALSE | R9: FALSE | S9: FALSE | T9: FALSE | U9: FALSE | V9: FALSE | W9: FALSE | X9: FALSE | Y9: FALSE | Z9: FALSE | AA9: FALSE | AB9: FALSE | AC9: FALSE | AD9: =COUNTIF(Match_Attendance[[#This Row],[Alf M]:[Ronnie D]],"Y") -> 0
A10: =Fixtures[[#This Row],[Date]] -> 46327 | B10: =Match_Attendance[[#This Row],[Date]] -> 46327 | C10: =Fixtures[[#This Row],[Opposition]] -> 0 | D10: FALSE | E10: FALSE | F10: FALSE | G10: FALSE | H10: FALSE | I10: FALSE | J10: FALSE | K10: FALSE | L10: FALSE | M10: FALSE | N10: FALSE | O10: FALSE | P10: FALSE | Q10: FALSE | R10: FALSE | S10: FALSE | T10: FALSE | U10: FALSE | V10: FALSE | W10: FALSE | X10: FALSE | Y10: FALSE | Z10: FALSE | AA10: FALSE | AB10: FALSE | AC10: FALSE | AD10: =COUNTIF(Match_Attendance[[#This Row],[Alf M]:[Ronnie D]],"Y") -> 0
A11: =Fixtures[[#This Row],[Date]] -> 46334 | B11: =Match_Attendance[[#This Row],[Date]] -> 46334 | C11: =Fixtures[[#This Row],[Opposition]] -> 0 | D11: FALSE | E11: FALSE | F11: FALSE | G11: FALSE | H11: FALSE | I11: FALSE | J11: FALSE | K11: FALSE | L11: FALSE | M11: FALSE | N11: FALSE | O11: FALSE | P11: FALSE | Q11: FALSE | R11: FALSE | S11: FALSE | T11: FALSE | U11: FALSE | V11: FALSE | W11: FALSE | X11: FALSE | Y11: FALSE | Z11: FALSE | AA11: FALSE | AB11: FALSE | AC11: FALSE | AD11: =COUNTIF(Match_Attendance[[#This Row],[Alf M]:[Ronnie D]],"Y") -> 0
A12: =Fixtures[[#This Row],[Date]] -> 46341 | B12: =Match_Attendance[[#This Row],[Date]] -> 46341 | C12: =Fixtures[[#This Row],[Opposition]] -> 0 | D12: FALSE | E12: FALSE | F12: FALSE | G12: FALSE | H12: FALSE | I12: FALSE | J12: FALSE | K12: FALSE | L12: FALSE | M12: FALSE | N12: FALSE | O12: FALSE | P12: FALSE | Q12: FALSE | R12: FALSE | S12: FALSE | T12: FALSE | U12: FALSE | V12: FALSE | W12: FALSE | X12: FALSE | Y12: FALSE | Z12: FALSE | AA12: FALSE | AB12: FALSE | AC12: FALSE | AD12: =COUNTIF(Match_Attendance[[#This Row],[Alf M]:[Ronnie D]],"Y") -> 0
A13: =Fixtures[[#This Row],[Date]] -> 46348 | B13: =Match_Attendance[[#This Row],[Date]] -> 46348 | C13: =Fixtures[[#This Row],[Opposition]] -> 0 | D13: FALSE | E13: FALSE | F13: FALSE | G13: FALSE | H13: FALSE | I13: FALSE | J13: FALSE | K13: FALSE | L13: FALSE | M13: FALSE | N13: FALSE | O13: FALSE | P13: FALSE | Q13: FALSE | R13: FALSE | S13: FALSE | T13: FALSE | U13: FALSE | V13: FALSE | W13: FALSE | X13: FALSE | Y13: FALSE | Z13: FALSE | AA13: FALSE | AB13: FALSE | AC13: FALSE | AD13: =COUNTIF(Match_Attendance[[#This Row],[Alf M]:[Ronnie D]],"Y") -> 0
... A53: =Fixtures[[#This Row],[Date]] -> 46628 | B53: =Match_Attendance[[#This Row],[Date]] -> 46628 | C53: =Fixtures[[#This Row],[Opposition]] -> 0 | D53: FALSE | E53: FALSE | F53: FALSE | G53: FALSE | H53: FALSE | I53: FALSE | J53: FALSE | K53: FALSE | L53: FALSE | M53: FALSE | N53: FALSE | O53: FALSE | P53: FALSE | Q53: FALSE | R53: FALSE | S53: FALSE | T53: FALSE | U53: FALSE | V53: FALSE | W53: FALSE | X53: FALSE | Y53: FALSE | Z53: FALSE | AA53: FALSE | AB53: FALSE | AC53: FALSE | AD53: =COUNTIF(Match_Attendance[[#This Row],[Alf M]:[Ronnie D]],"Y") -> 0
C54: Total | D54: =COUNTIF(Match_Attendance[Alf M],TRUE) -> 0 | E54: =COUNTIF(Match_Attendance[Alfie F],TRUE) -> 0 | F54: =COUNTIF(Match_Attendance[Bailey],TRUE) -> 0 | G54: =COUNTIF(Match_Attendance[Brad],TRUE) -> 0 | H54: =COUNTIF(Match_Attendance[Callum],TRUE) -> 0 | I54: =COUNTIF(Match_Attendance[Danny],TRUE) -> 0 | J54: =COUNTIF(Match_Attendance[Ethan],TRUE) -> 0 | K54: =COUNTIF(Match_Attendance[Freddie],TRUE) -> 0 | L54: =COUNTIF(Match_Attendance[George],TRUE) -> 0 | M54: =COUNTIF(Match_Attendance[Jamie],TRUE) -> 0 | N54: =COUNTIF(Match_Attendance[Jay],TRUE) -> 0 | O54: =COUNTIF(Match_Attendance[Joe],TRUE) -> 0 | P54: =COUNTIF(Match_Attendance[Josh],TRUE) -> 0 | Q54: =COUNTIF(Match_Attendance[Jude],TRUE) -> 0 | R54: =COUNTIF(Match_Attendance[Kalan],TRUE) -> 0 | S54: =COUNTIF(Match_Attendance[Kazeem],TRUE) -> 0 | T54: =COUNTIF(Match_Attendance[Keiran D],TRUE) -> 0 | U54: =COUNTIF(Match_Attendance[Keiran R],TRUE) -> 0 | V54: =COUNTIF(Match_Attendance[Liam],TRUE) -> 0 | W54: =COUNTIF(Match_Attendance[Louie],TRUE) -> 0 | X54: =COUNTIF(Match_Attendance[Rocco],TRUE) -> 0 | Y54: =COUNTIF(Match_Attendance[Ronnie D],TRUE) -> 0 | Z54: =COUNTIF(Match_Attendance[Ronnie T],TRUE) -> 0 | AA54: =COUNTIF(Match_Attendance[Ryan],TRUE) -> 0 | AB54: =COUNTIF(Match_Attendance[Ryeley],TRUE) -> 0 | AC54: =COUNTIF(Match_Attendance[Will],TRUE) -> 0 | AD54: =SUBTOTAL(109,Match_Attendance[COUNT]) -> 0
C58: Games Rotated | D58: =COUNTIF(Match_Attendance[Alf M], "R") -> 0 | E58: =COUNTIF(Match_Attendance[Alfie F], "R") -> 0 | F58: =COUNTIF(Match_Attendance[Bailey], "R") -> 0 | G58: =COUNTIF(Match_Attendance[Brad], "R") -> 0 | H58: =COUNTIF(Match_Attendance[Callum], "R") -> 0 | I58: =COUNTIF(Match_Attendance[Danny], "R") -> 0 | J58: =COUNTIF(Match_Attendance[Ethan], "R") -> 0 | K58: =COUNTIF(Match_Attendance[Freddie], "R") -> 0 | L58: =COUNTIF(Match_Attendance[George], "R") -> 0 | M58: =COUNTIF(Match_Attendance[Jamie], "R") -> 0 | N58: =COUNTIF(Match_Attendance[Jay], "R") -> 0 | O58: =COUNTIF(Match_Attendance[Joe], "R") -> 0 | P58: =COUNTIF(Match_Attendance[Josh], "R") -> 0 | Q58: =COUNTIF(Match_Attendance[Jude], "R") -> 0 | R58: =COUNTIF(Match_Attendance[Kalan], "R") -> 0 | S58: =COUNTIF(Match_Attendance[Kazeem], "R") -> 0 | T58: =COUNTIF(Match_Attendance[Keiran D], "R") -> 0 | U58: =COUNTIF(Match_Attendance[Keiran R], "R") -> 0 | V58: =COUNTIF(Match_Attendance[Liam], "R") -> 0 | W58: =COUNTIF(Match_Attendance[Louie], "R") -> 0 | X58: =COUNTIF(Match_Attendance[Rocco], "R") -> 0 | Y58: =COUNTIF(Match_Attendance[Ronnie D], "R") -> 0 | Z58: =COUNTIF(Match_Attendance[Ronnie T], "R") -> 0 | AA58: =COUNTIF(Match_Attendance[Ryan], "R") -> 0 | AB58: =COUNTIF(Match_Attendance[Ryeley], "R") -> 0 | AC58: =COUNTIF(Match_Attendance[Will], "R") -> 0
C60: Games Injured | D60: =COUNTIF(Match_Attendance[Alf M], "I") -> 0 | E60: =COUNTIF(Match_Attendance[Alfie F], "I") -> 0 | F60: =COUNTIF(Match_Attendance[Bailey], "I") -> 0 | G60: =COUNTIF(Match_Attendance[Brad], "I") -> 0 | H60: =COUNTIF(Match_Attendance[Callum], "I") -> 0 | I60: =COUNTIF(Match_Attendance[Danny], "I") -> 0 | J60: =COUNTIF(Match_Attendance[Ethan], "I") -> 0 | K60: =COUNTIF(Match_Attendance[Freddie], "I") -> 0 | L60: =COUNTIF(Match_Attendance[George], "I") -> 0 | M60: =COUNTIF(Match_Attendance[Jamie], "I") -> 0 | N60: =COUNTIF(Match_Attendance[Jay], "I") -> 0 | O60: =COUNTIF(Match_Attendance[Joe], "I") -> 0 | P60: =COUNTIF(Match_Attendance[Josh], "I") -> 0 | Q60: =COUNTIF(Match_Attendance[Jude], "I") -> 0 | R60: =COUNTIF(Match_Attendance[Kalan], "I") -> 0 | S60: =COUNTIF(Match_Attendance[Kazeem], "I") -> 0 | T60: =COUNTIF(Match_Attendance[Keiran D], "I") -> 0 | U60: =COUNTIF(Match_Attendance[Keiran R], "I") -> 0 | V60: =COUNTIF(Match_Attendance[Liam], "I") -> 0 | W60: =COUNTIF(Match_Attendance[Louie], "I") -> 0 | X60: =COUNTIF(Match_Attendance[Rocco], "I") -> 0 | Y60: =COUNTIF(Match_Attendance[Ronnie D], "I") -> 0 | Z60: =COUNTIF(Match_Attendance[Ronnie T], "I") -> 0 | AA60: =COUNTIF(Match_Attendance[Ryan], "I") -> 0 | AB60: =COUNTIF(Match_Attendance[Ryeley], "I") -> 0 | AC60: =COUNTIF(Match_Attendance[Will], "I") -> 0

Sheet Training Attendance
A1: Date | B1: Day | C1: Session | D1: Alf M | E1: Alfie F | F1: Bailey | G1: Brad | H1: Callum | I1: Danny | J1: Ethan | K1: Freddie | L1: George | M1: Jamie | N1: Jay | O1: Joe | P1: Josh | Q1: Jude | R1: Kalan | S1: Kazeem | T1: Keiran D | U1: Keiran R | V1: Liam | W1: Louie | X1: Rocco | Y1: Ronnie D | Z1: Ronnie T | AA1: Ryan | AB1: Ryeley | AC1: Will | AD1: COUNT
A2: 46267 | B2: =Training_Attendance[[#This Row],[Date]] -> 46267 | C2: Training | D2: {=IF(SUMPRODUCT(IFERROR(--(INT(Attendance[Start time])=Training_Attendance[[#This Row],[Date]]),0)*IFERROR(--(ISNUMBER(SEARCH(D$1,Attendance[Attendees]))),0)*IFERROR(--(Attendance[Session Type]="Training"),0))>0,"Y","")} | E2: {=IF(SUMPRODUCT(IFERROR(--(INT(Attendance[Start time])=Training_Attendance[[#This Row],[Date]]),0)*IFERROR(--(ISNUMBER(SEARCH(E$1,Attendance[Attendees]))),0)*IFERROR(--(Attendance[Session Type]="Training"),0))>0,"Y","")} | F2: {=IF(SUMPRODUCT(IFERROR(--(INT(Attendance[Start time])=Training_Attendance[[#This Row],[Date]]),0)*IFERROR(--(ISNUMBER(SEARCH(F$1,Attendance[Attendees]))),0)*IFERROR(--(Attendance[Session Type]="Training"),0))>0,"Y","")} | G2: {=IF(SUMPRODUCT(IFERROR(--(INT(Attendance[Start time])=Training_Attendance[[#This Row],[Date]]),0)*IFERROR(--(ISNUMBER(SEARCH(G$1,Attendance[Attendees]))),0)*IFERROR(--(Attendance[Session Type]="Training"),0))>0,"Y","")} | H2: {=IF(SUMPRODUCT(IFERROR(--(INT(Attendance[Start time])=Training_Attendance[[#This Row],[Date]]),0)*IFERROR(--(ISNUMBER(SEARCH(H$1,Attendance[Attendees]))),0)*IFERROR(--(Attendance[Session Type]="Training"),0))>0,"Y","")} | I2: {=IF(SUMPRODUCT(IFERROR(--(INT(Attendance[Start time])=Training_Attendance[[#This Row],[Date]]),0)*IFERROR(--(ISNUMBER(SEARCH(I$1,Attendance[Attendees]))),0)*IFERROR(--(Attendance[Session Type]="Training"),0))>0,"Y","")} | J2: {=IF(SUMPRODUCT(IFERROR(--(INT(Attendance[Start time])=Training_Attendance[[#This Row],[Date]]),0)*IFERROR(--(ISNUMBER(SEARCH(J$1,Attendance[Attendees]))),0)*IFERROR(--(Attendance[Session Type]="Training"),0))>0,"Y","")} | K2: {=IF(SUMPRODUCT(IFERROR(--(INT(Attendance[Start time])=Training_Attendance[[#This Row],[Date]]),0)*IFERROR(--(ISNUMBER(SEARCH(K$1,Attendance[Attendees]))),0)*IFERROR(--(Attendance[Session Type]="Training"),0))>0,"Y","")} | ... AC2: {=IF(SUMPRODUCT(IFERROR(--(INT(Attendance[Start time])=Training_Attendance[[#This Row],[Date]]),0)*IFERROR(--(ISNUMBER(SEARCH(AC$1,Attendance[Attendees]))),0)*IFERROR(--(Attendance[Session Type]="Training"),0))>0,"Y","")} | AD2: =COUNTIF(Training_Attendance[[#This Row],[Alf M]:[Ronnie D]],"Y") -> 0
A3: 46274 | B3: =Training_Attendance[[#This Row],[Date]] -> 46274 | C3: Training | D3: {=IF(SUMPRODUCT(IFERROR(--(INT(Attendance[Start time])=Training_Attendance[[#This Row],[Date]]),0)*IFERROR(--(ISNUMBER(SEARCH(D$1,Attendance[Attendees]))),0)*IFERROR(--(Attendance[Session Type]="Training"),0))>0,"Y","")} | E3: {=IF(SUMPRODUCT(IFERROR(--(INT(Attendance[Start time])=Training_Attendance[[#This Row],[Date]]),0)*IFERROR(--(ISNUMBER(SEARCH(E$1,Attendance[Attendees]))),0)*IFERROR(--(Attendance[Session Type]="Training"),0))>0,"Y","")} | F3: {=IF(SUMPRODUCT(IFERROR(--(INT(Attendance[Start time])=Training_Attendance[[#This Row],[Date]]),0)*IFERROR(--(ISNUMBER(SEARCH(F$1,Attendance[Attendees]))),0)*IFERROR(--(Attendance[Session Type]="Training"),0))>0,"Y","")} | G3: {=IF(SUMPRODUCT(IFERROR(--(INT(Attendance[Start time])=Training_Attendance[[#This Row],[Date]]),0)*IFERROR(--(ISNUMBER(SEARCH(G$1,Attendance[Attendees]))),0)*IFERROR(--(Attendance[Session Type]="Training"),0))>0,"Y","")} | H3: {=IF(SUMPRODUCT(IFERROR(--(INT(Attendance[Start time])=Training_Attendance[[#This Row],[Date]]),0)*IFERROR(--(ISNUMBER(SEARCH(H$1,Attendance[Attendees]))),0)*IFERROR(--(Attendance[Session Type]="Training"),0))>0,"Y","")} | I3: {=IF(SUMPRODUCT(IFERROR(--(INT(Attendance[Start time])=Training_Attendance[[#This Row],[Date]]),0)*IFERROR(--(ISNUMBER(SEARCH(I$1,Attendance[Attendees]))),0)*IFERROR(--(Attendance[Session Type]="Training"),0))>0,"Y","")} | J3: {=IF(SUMPRODUCT(IFERROR(--(INT(Attendance[Start time])=Training_Attendance[[#This Row],[Date]]),0)*IFERROR(--(ISNUMBER(SEARCH(J$1,Attendance[Attendees]))),0)*IFERROR(--(Attendance[Session Type]="Training"),0))>0,"Y","")} | K3: {=IF(SUMPRODUCT(IFERROR(--(INT(Attendance[Start time])=Training_Attendance[[#This Row],[Date]]),0)*IFERROR(--(ISNUMBER(SEARCH(K$1,Attendance[Attendees]))),0)*IFERROR(--(Attendance[Session Type]="Training"),0))>0,"Y","")} | ... AC3: {=IF(SUMPRODUCT(IFERROR(--(INT(Attendance[Start time])=Training_Attendance[[#This Row],[Date]]),0)*IFERROR(--(ISNUMBER(SEARCH(AC$1,Attendance[Attendees]))),0)*IFERROR(--(Attendance[Session Type]="Training"),0))>0,"Y","")} | AD3: =COUNTIF(Training_Attendance[[#This Row],[Alf M]:[Ronnie D]],"Y") -> 0
A4: 46281 | B4: =Training_Attendance[[#This Row],[Date]] -> 46281 | C4: Training | D4: {=IF(SUMPRODUCT(IFERROR(--(INT(Attendance[Start time])=Training_Attendance[[#This Row],[Date]]),0)*IFERROR(--(ISNUMBER(SEARCH(D$1,Attendance[Attendees]))),0)*IFERROR(--(Attendance[Session Type]="Training"),0))>0,"Y","")} | E4: {=IF(SUMPRODUCT(IFERROR(--(INT(Attendance[Start time])=Training_Attendance[[#This Row],[Date]]),0)*IFERROR(--(ISNUMBER(SEARCH(E$1,Attendance[Attendees]))),0)*IFERROR(--(Attendance[Session Type]="Training"),0))>0,"Y","")} | F4: {=IF(SUMPRODUCT(IFERROR(--(INT(Attendance[Start time])=Training_Attendance[[#This Row],[Date]]),0)*IFERROR(--(ISNUMBER(SEARCH(F$1,Attendance[Attendees]))),0)*IFERROR(--(Attendance[Session Type]="Training"),0))>0,"Y","")} | G4: {=IF(SUMPRODUCT(IFERROR(--(INT(Attendance[Start time])=Training_Attendance[[#This Row],[Date]]),0)*IFERROR(--(ISNUMBER(SEARCH(G$1,Attendance[Attendees]))),0)*IFERROR(--(Attendance[Session Type]="Training"),0))>0,"Y","")} | H4: {=IF(SUMPRODUCT(IFERROR(--(INT(Attendance[Start time])=Training_Attendance[[#This Row],[Date]]),0)*IFERROR(--(ISNUMBER(SEARCH(H$1,Attendance[Attendees]))),0)*IFERROR(--(Attendance[Session Type]="Training"),0))>0,"Y","")} | I4: {=IF(SUMPRODUCT(IFERROR(--(INT(Attendance[Start time])=Training_Attendance[[#This Row],[Date]]),0)*IFERROR(--(ISNUMBER(SEARCH(I$1,Attendance[Attendees]))),0)*IFERROR(--(Attendance[Session Type]="Training"),0))>0,"Y","")} | J4: {=IF(SUMPRODUCT(IFERROR(--(INT(Attendance[Start time])=Training_Attendance[[#This Row],[Date]]),0)*IFERROR(--(ISNUMBER(SEARCH(J$1,Attendance[Attendees]))),0)*IFERROR(--(Attendance[Session Type]="Training"),0))>0,"Y","")} | K4: {=IF(SUMPRODUCT(IFERROR(--(INT(Attendance[Start time])=Training_Attendance[[#This Row],[Date]]),0)*IFERROR(--(ISNUMBER(SEARCH(K$1,Attendance[Attendees]))),0)*IFERROR(--(Attendance[Session Type]="Training"),0))>0,"Y","")} | ... AC4: {=IF(SUMPRODUCT(IFERROR(--(INT(Attendance[Start time])=Training_Attendance[[#This Row],[Date]]),0)*IFERROR(--(ISNUMBER(SEARCH(AC$1,Attendance[Attendees]))),0)*IFERROR(--(Attendance[Session Type]="Training"),0))>0,"Y","")} | AD4: =COUNTIF(Training_Attendance[[#This Row],[Alf M]:[Ronnie D]],"Y") -> 0
A5: 46288 | B5: =Training_Attendance[[#This Row],[Date]] -> 46288 | C5: Training | D5: {=IF(SUMPRODUCT(IFERROR(--(INT(Attendance[Start time])=Training_Attendance[[#This Row],[Date]]),0)*IFERROR(--(ISNUMBER(SEARCH(D$1,Attendance[Attendees]))),0)*IFERROR(--(Attendance[Session Type]="Training"),0))>0,"Y","")} | E5: {=IF(SUMPRODUCT(IFERROR(--(INT(Attendance[Start time])=Training_Attendance[[#This Row],[Date]]),0)*IFERROR(--(ISNUMBER(SEARCH(E$1,Attendance[Attendees]))),0)*IFERROR(--(Attendance[Session Type]="Training"),0))>0,"Y","")} | F5: {=IF(SUMPRODUCT(IFERROR(--(INT(Attendance[Start time])=Training_Attendance[[#This Row],[Date]]),0)*IFERROR(--(ISNUMBER(SEARCH(F$1,Attendance[Attendees]))),0)*IFERROR(--(Attendance[Session Type]="Training"),0))>0,"Y","")} | G5: {=IF(SUMPRODUCT(IFERROR(--(INT(Attendance[Start time])=Training_Attendance[[#This Row],[Date]]),0)*IFERROR(--(ISNUMBER(SEARCH(G$1,Attendance[Attendees]))),0)*IFERROR(--(Attendance[Session Type]="Training"),0))>0,"Y","")} | H5: {=IF(SUMPRODUCT(IFERROR(--(INT(Attendance[Start time])=Training_Attendance[[#This Row],[Date]]),0)*IFERROR(--(ISNUMBER(SEARCH(H$1,Attendance[Attendees]))),0)*IFERROR(--(Attendance[Session Type]="Training"),0))>0,"Y","")} | I5: {=IF(SUMPRODUCT(IFERROR(--(INT(Attendance[Start time])=Training_Attendance[[#This Row],[Date]]),0)*IFERROR(--(ISNUMBER(SEARCH(I$1,Attendance[Attendees]))),0)*IFERROR(--(Attendance[Session Type]="Training"),0))>0,"Y","")} | J5: {=IF(SUMPRODUCT(IFERROR(--(INT(Attendance[Start time])=Training_Attendance[[#This Row],[Date]]),0)*IFERROR(--(ISNUMBER(SEARCH(J$1,Attendance[Attendees]))),0)*IFERROR(--(Attendance[Session Type]="Training"),0))>0,"Y","")} | K5: {=IF(SUMPRODUCT(IFERROR(--(INT(Attendance[Start time])=Training_Attendance[[#This Row],[Date]]),0)*IFERROR(--(ISNUMBER(SEARCH(K$1,Attendance[Attendees]))),0)*IFERROR(--(Attendance[Session Type]="Training"),0))>0,"Y","")} | ... AC5: {=IF(SUMPRODUCT(IFERROR(--(INT(Attendance[Start time])=Training_Attendance[[#This Row],[Date]]),0)*IFERROR(--(ISNUMBER(SEARCH(AC$1,Attendance[Attendees]))),0)*IFERROR(--(Attendance[Session Type]="Training"),0))>0,"Y","")} | AD5: =COUNTIF(Training_Attendance[[#This Row],[Alf M]:[Ronnie D]],"Y") -> 0
A6: 46295 | B6: =Training_Attendance[[#This Row],[Date]] -> 46295 | C6: Training | D6: {=IF(SUMPRODUCT(IFERROR(--(INT(Attendance[Start time])=Training_Attendance[[#This Row],[Date]]),0)*IFERROR(--(ISNUMBER(SEARCH(D$1,Attendance[Attendees]))),0)*IFERROR(--(Attendance[Session Type]="Training"),0))>0,"Y","")} | E6: {=IF(SUMPRODUCT(IFERROR(--(INT(Attendance[Start time])=Training_Attendance[[#This Row],[Date]]),0)*IFERROR(--(ISNUMBER(SEARCH(E$1,Attendance[Attendees]))),0)*IFERROR(--(Attendance[Session Type]="Training"),0))>0,"Y","")} | F6: {=IF(SUMPRODUCT(IFERROR(--(INT(Attendance[Start time])=Training_Attendance[[#This Row],[Date]]),0)*IFERROR(--(ISNUMBER(SEARCH(F$1,Attendance[Attendees]))),0)*IFERROR(--(Attendance[Session Type]="Training"),0))>0,"Y","")} | G6: {=IF(SUMPRODUCT(IFERROR(--(INT(Attendance[Start time])=Training_Attendance[[#This Row],[Date]]),0)*IFERROR(--(ISNUMBER(SEARCH(G$1,Attendance[Attendees]))),0)*IFERROR(--(Attendance[Session Type]="Training"),0))>0,"Y","")} | H6: {=IF(SUMPRODUCT(IFERROR(--(INT(Attendance[Start time])=Training_Attendance[[#This Row],[Date]]),0)*IFERROR(--(ISNUMBER(SEARCH(H$1,Attendance[Attendees]))),0)*IFERROR(--(Attendance[Session Type]="Training"),0))>0,"Y","")} | I6: {=IF(SUMPRODUCT(IFERROR(--(INT(Attendance[Start time])=Training_Attendance[[#This Row],[Date]]),0)*IFERROR(--(ISNUMBER(SEARCH(I$1,Attendance[Attendees]))),0)*IFERROR(--(Attendance[Session Type]="Training"),0))>0,"Y","")} | J6: {=IF(SUMPRODUCT(IFERROR(--(INT(Attendance[Start time])=Training_Attendance[[#This Row],[Date]]),0)*IFERROR(--(ISNUMBER(SEARCH(J$1,Attendance[Attendees]))),0)*IFERROR(--(Attendance[Session Type]="Training"),0))>0,"Y","")} | K6: {=IF(SUMPRODUCT(IFERROR(--(INT(Attendance[Start time])=Training_Attendance[[#This Row],[Date]]),0)*IFERROR(--(ISNUMBER(SEARCH(K$1,Attendance[Attendees]))),0)*IFERROR(--(Attendance[Session Type]="Training"),0))>0,"Y","")} | ... AC6: {=IF(SUMPRODUCT(IFERROR(--(INT(Attendance[Start time])=Training_Attendance[[#This Row],[Date]]),0)*IFERROR(--(ISNUMBER(SEARCH(AC$1,Attendance[Attendees]))),0)*IFERROR(--(Attendance[Session Type]="Training"),0))>0,"Y","")} | AD6: =COUNTIF(Training_Attendance[[#This Row],[Alf M]:[Ronnie D]],"Y") -> 0
A7: 46302 | B7: =Training_Attendance[[#This Row],[Date]] -> 46302 | C7: Training | D7: {=IF(SUMPRODUCT(IFERROR(--(INT(Attendance[Start time])=Training_Attendance[[#This Row],[Date]]),0)*IFERROR(--(ISNUMBER(SEARCH(D$1,Attendance[Attendees]))),0)*IFERROR(--(Attendance[Session Type]="Training"),0))>0,"Y","")} | E7: {=IF(SUMPRODUCT(IFERROR(--(INT(Attendance[Start time])=Training_Attendance[[#This Row],[Date]]),0)*IFERROR(--(ISNUMBER(SEARCH(E$1,Attendance[Attendees]))),0)*IFERROR(--(Attendance[Session Type]="Training"),0))>0,"Y","")} | F7: {=IF(SUMPRODUCT(IFERROR(--(INT(Attendance[Start time])=Training_Attendance[[#This Row],[Date]]),0)*IFERROR(--(ISNUMBER(SEARCH(F$1,Attendance[Attendees]))),0)*IFERROR(--(Attendance[Session Type]="Training"),0))>0,"Y","")} | G7: {=IF(SUMPRODUCT(IFERROR(--(INT(Attendance[Start time])=Training_Attendance[[#This Row],[Date]]),0)*IFERROR(--(ISNUMBER(SEARCH(G$1,Attendance[Attendees]))),0)*IFERROR(--(Attendance[Session Type]="Training"),0))>0,"Y","")} | H7: {=IF(SUMPRODUCT(IFERROR(--(INT(Attendance[Start time])=Training_Attendance[[#This Row],[Date]]),0)*IFERROR(--(ISNUMBER(SEARCH(H$1,Attendance[Attendees]))),0)*IFERROR(--(Attendance[Session Type]="Training"),0))>0,"Y","")} | I7: {=IF(SUMPRODUCT(IFERROR(--(INT(Attendance[Start time])=Training_Attendance[[#This Row],[Date]]),0)*IFERROR(--(ISNUMBER(SEARCH(I$1,Attendance[Attendees]))),0)*IFERROR(--(Attendance[Session Type]="Training"),0))>0,"Y","")} | J7: {=IF(SUMPRODUCT(IFERROR(--(INT(Attendance[Start time])=Training_Attendance[[#This Row],[Date]]),0)*IFERROR(--(ISNUMBER(SEARCH(J$1,Attendance[Attendees]))),0)*IFERROR(--(Attendance[Session Type]="Training"),0))>0,"Y","")} | K7: {=IF(SUMPRODUCT(IFERROR(--(INT(Attendance[Start time])=Training_Attendance[[#This Row],[Date]]),0)*IFERROR(--(ISNUMBER(SEARCH(K$1,Attendance[Attendees]))),0)*IFERROR(--(Attendance[Session Type]="Training"),0))>0,"Y","")} | ... AC7: {=IF(SUMPRODUCT(IFERROR(--(INT(Attendance[Start time])=Training_Attendance[[#This Row],[Date]]),0)*IFERROR(--(ISNUMBER(SEARCH(AC$1,Attendance[Attendees]))),0)*IFERROR(--(Attendance[Session Type]="Training"),0))>0,"Y","")} | AD7: =COUNTIF(Training_Attendance[[#This Row],[Alf M]:[Ronnie D]],"Y") -> 0
A8: 46309 | B8: =Training_Attendance[[#This Row],[Date]] -> 46309 | C8: Training | D8: {=IF(SUMPRODUCT(IFERROR(--(INT(Attendance[Start time])=Training_Attendance[[#This Row],[Date]]),0)*IFERROR(--(ISNUMBER(SEARCH(D$1,Attendance[Attendees]))),0)*IFERROR(--(Attendance[Session Type]="Training"),0))>0,"Y","")} | E8: {=IF(SUMPRODUCT(IFERROR(--(INT(Attendance[Start time])=Training_Attendance[[#This Row],[Date]]),0)*IFERROR(--(ISNUMBER(SEARCH(E$1,Attendance[Attendees]))),0)*IFERROR(--(Attendance[Session Type]="Training"),0))>0,"Y","")} | F8: {=IF(SUMPRODUCT(IFERROR(--(INT(Attendance[Start time])=Training_Attendance[[#This Row],[Date]]),0)*IFERROR(--(ISNUMBER(SEARCH(F$1,Attendance[Attendees]))),0)*IFERROR(--(Attendance[Session Type]="Training"),0))>0,"Y","")} | G8: {=IF(SUMPRODUCT(IFERROR(--(INT(Attendance[Start time])=Training_Attendance[[#This Row],[Date]]),0)*IFERROR(--(ISNUMBER(SEARCH(G$1,Attendance[Attendees]))),0)*IFERROR(--(Attendance[Session Type]="Training"),0))>0,"Y","")} | H8: {=IF(SUMPRODUCT(IFERROR(--(INT(Attendance[Start time])=Training_Attendance[[#This Row],[Date]]),0)*IFERROR(--(ISNUMBER(SEARCH(H$1,Attendance[Attendees]))),0)*IFERROR(--(Attendance[Session Type]="Training"),0))>0,"Y","")} | I8: {=IF(SUMPRODUCT(IFERROR(--(INT(Attendance[Start time])=Training_Attendance[[#This Row],[Date]]),0)*IFERROR(--(ISNUMBER(SEARCH(I$1,Attendance[Attendees]))),0)*IFERROR(--(Attendance[Session Type]="Training"),0))>0,"Y","")} | J8: {=IF(SUMPRODUCT(IFERROR(--(INT(Attendance[Start time])=Training_Attendance[[#This Row],[Date]]),0)*IFERROR(--(ISNUMBER(SEARCH(J$1,Attendance[Attendees]))),0)*IFERROR(--(Attendance[Session Type]="Training"),0))>0,"Y","")} | K8: {=IF(SUMPRODUCT(IFERROR(--(INT(Attendance[Start time])=Training_Attendance[[#This Row],[Date]]),0)*IFERROR(--(ISNUMBER(SEARCH(K$1,Attendance[Attendees]))),0)*IFERROR(--(Attendance[Session Type]="Training"),0))>0,"Y","")} | ... AC8: {=IF(SUMPRODUCT(IFERROR(--(INT(Attendance[Start time])=Training_Attendance[[#This Row],[Date]]),0)*IFERROR(--(ISNUMBER(SEARCH(AC$1,Attendance[Attendees]))),0)*IFERROR(--(Attendance[Session Type]="Training"),0))>0,"Y","")} | AD8: =COUNTIF(Training_Attendance[[#This Row],[Alf M]:[Ronnie D]],"Y") -> 0
A9: 46316 | B9: =Training_Attendance[[#This Row],[Date]] -> 46316 | C9: Training | D9: {=IF(SUMPRODUCT(IFERROR(--(INT(Attendance[Start time])=Training_Attendance[[#This Row],[Date]]),0)*IFERROR(--(ISNUMBER(SEARCH(D$1,Attendance[Attendees]))),0)*IFERROR(--(Attendance[Session Type]="Training"),0))>0,"Y","")} | E9: {=IF(SUMPRODUCT(IFERROR(--(INT(Attendance[Start time])=Training_Attendance[[#This Row],[Date]]),0)*IFERROR(--(ISNUMBER(SEARCH(E$1,Attendance[Attendees]))),0)*IFERROR(--(Attendance[Session Type]="Training"),0))>0,"Y","")} | F9: {=IF(SUMPRODUCT(IFERROR(--(INT(Attendance[Start time])=Training_Attendance[[#This Row],[Date]]),0)*IFERROR(--(ISNUMBER(SEARCH(F$1,Attendance[Attendees]))),0)*IFERROR(--(Attendance[Session Type]="Training"),0))>0,"Y","")} | G9: {=IF(SUMPRODUCT(IFERROR(--(INT(Attendance[Start time])=Training_Attendance[[#This Row],[Date]]),0)*IFERROR(--(ISNUMBER(SEARCH(G$1,Attendance[Attendees]))),0)*IFERROR(--(Attendance[Session Type]="Training"),0))>0,"Y","")} | H9: {=IF(SUMPRODUCT(IFERROR(--(INT(Attendance[Start time])=Training_Attendance[[#This Row],[Date]]),0)*IFERROR(--(ISNUMBER(SEARCH(H$1,Attendance[Attendees]))),0)*IFERROR(--(Attendance[Session Type]="Training"),0))>0,"Y","")} | I9: {=IF(SUMPRODUCT(IFERROR(--(INT(Attendance[Start time])=Training_Attendance[[#This Row],[Date]]),0)*IFERROR(--(ISNUMBER(SEARCH(I$1,Attendance[Attendees]))),0)*IFERROR(--(Attendance[Session Type]="Training"),0))>0,"Y","")} | J9: {=IF(SUMPRODUCT(IFERROR(--(INT(Attendance[Start time])=Training_Attendance[[#This Row],[Date]]),0)*IFERROR(--(ISNUMBER(SEARCH(J$1,Attendance[Attendees]))),0)*IFERROR(--(Attendance[Session Type]="Training"),0))>0,"Y","")} | K9: {=IF(SUMPRODUCT(IFERROR(--(INT(Attendance[Start time])=Training_Attendance[[#This Row],[Date]]),0)*IFERROR(--(ISNUMBER(SEARCH(K$1,Attendance[Attendees]))),0)*IFERROR(--(Attendance[Session Type]="Training"),0))>0,"Y","")} | ... AC9: {=IF(SUMPRODUCT(IFERROR(--(INT(Attendance[Start time])=Training_Attendance[[#This Row],[Date]]),0)*IFERROR(--(ISNUMBER(SEARCH(AC$1,Attendance[Attendees]))),0)*IFERROR(--(Attendance[Session Type]="Training"),0))>0,"Y","")} | AD9: =COUNTIF(Training_Attendance[[#This Row],[Alf M]:[Ronnie D]],"Y") -> 0
A10: 46323 | B10: =Training_Attendance[[#This Row],[Date]] -> 46323 | C10: Training | D10: {=IF(SUMPRODUCT(IFERROR(--(INT(Attendance[Start time])=Training_Attendance[[#This Row],[Date]]),0)*IFERROR(--(ISNUMBER(SEARCH(D$1,Attendance[Attendees]))),0)*IFERROR(--(Attendance[Session Type]="Training"),0))>0,"Y","")} | E10: {=IF(SUMPRODUCT(IFERROR(--(INT(Attendance[Start time])=Training_Attendance[[#This Row],[Date]]),0)*IFERROR(--(ISNUMBER(SEARCH(E$1,Attendance[Attendees]))),0)*IFERROR(--(Attendance[Session Type]="Training"),0))>0,"Y","")} | F10: {=IF(SUMPRODUCT(IFERROR(--(INT(Attendance[Start time])=Training_Attendance[[#This Row],[Date]]),0)*IFERROR(--(ISNUMBER(SEARCH(F$1,Attendance[Attendees]))),0)*IFERROR(--(Attendance[Session Type]="Training"),0))>0,"Y","")} | G10: {=IF(SUMPRODUCT(IFERROR(--(INT(Attendance[Start time])=Training_Attendance[[#This Row],[Date]]),0)*IFERROR(--(ISNUMBER(SEARCH(G$1,Attendance[Attendees]))),0)*IFERROR(--(Attendance[Session Type]="Training"),0))>0,"Y","")} | H10: {=IF(SUMPRODUCT(IFERROR(--(INT(Attendance[Start time])=Training_Attendance[[#This Row],[Date]]),0)*IFERROR(--(ISNUMBER(SEARCH(H$1,Attendance[Attendees]))),0)*IFERROR(--(Attendance[Session Type]="Training"),0))>0,"Y","")} | I10: {=IF(SUMPRODUCT(IFERROR(--(INT(Attendance[Start time])=Training_Attendance[[#This Row],[Date]]),0)*IFERROR(--(ISNUMBER(SEARCH(I$1,Attendance[Attendees]))),0)*IFERROR(--(Attendance[Session Type]="Training"),0))>0,"Y","")} | J10: {=IF(SUMPRODUCT(IFERROR(--(INT(Attendance[Start time])=Training_Attendance[[#This Row],[Date]]),0)*IFERROR(--(ISNUMBER(SEARCH(J$1,Attendance[Attendees]))),0)*IFERROR(--(Attendance[Session Type]="Training"),0))>0,"Y","")} | K10: {=IF(SUMPRODUCT(IFERROR(--(INT(Attendance[Start time])=Training_Attendance[[#This Row],[Date]]),0)*IFERROR(--(ISNUMBER(SEARCH(K$1,Attendance[Attendees]))),0)*IFERROR(--(Attendance[Session Type]="Training"),0))>0,"Y","")} | ... AC10: {=IF(SUMPRODUCT(IFERROR(--(INT(Attendance[Start time])=Training_Attendance[[#This Row],[Date]]),0)*IFERROR(--(ISNUMBER(SEARCH(AC$1,Attendance[Attendees]))),0)*IFERROR(--(Attendance[Session Type]="Training"),0))>0,"Y","")} | AD10: =COUNTIF(Training_Attendance[[#This Row],[Alf M]:[Ronnie D]],"Y") -> 0
A11: 46330 | B11: =Training_Attendance[[#This Row],[Date]] -> 46330 | C11: Training | D11: {=IF(SUMPRODUCT(IFERROR(--(INT(Attendance[Start time])=Training_Attendance[[#This Row],[Date]]),0)*IFERROR(--(ISNUMBER(SEARCH(D$1,Attendance[Attendees]))),0)*IFERROR(--(Attendance[Session Type]="Training"),0))>0,"Y","")} | E11: {=IF(SUMPRODUCT(IFERROR(--(INT(Attendance[Start time])=Training_Attendance[[#This Row],[Date]]),0)*IFERROR(--(ISNUMBER(SEARCH(E$1,Attendance[Attendees]))),0)*IFERROR(--(Attendance[Session Type]="Training"),0))>0,"Y","")} | F11: {=IF(SUMPRODUCT(IFERROR(--(INT(Attendance[Start time])=Training_Attendance[[#This Row],[Date]]),0)*IFERROR(--(ISNUMBER(SEARCH(F$1,Attendance[Attendees]))),0)*IFERROR(--(Attendance[Session Type]="Training"),0))>0,"Y","")} | G11: {=IF(SUMPRODUCT(IFERROR(--(INT(Attendance[Start time])=Training_Attendance[[#This Row],[Date]]),0)*IFERROR(--(ISNUMBER(SEARCH(G$1,Attendance[Attendees]))),0)*IFERROR(--(Attendance[Session Type]="Training"),0))>0,"Y","")} | H11: {=IF(SUMPRODUCT(IFERROR(--(INT(Attendance[Start time])=Training_Attendance[[#This Row],[Date]]),0)*IFERROR(--(ISNUMBER(SEARCH(H$1,Attendance[Attendees]))),0)*IFERROR(--(Attendance[Session Type]="Training"),0))>0,"Y","")} | I11: {=IF(SUMPRODUCT(IFERROR(--(INT(Attendance[Start time])=Training_Attendance[[#This Row],[Date]]),0)*IFERROR(--(ISNUMBER(SEARCH(I$1,Attendance[Attendees]))),0)*IFERROR(--(Attendance[Session Type]="Training"),0))>0,"Y","")} | J11: {=IF(SUMPRODUCT(IFERROR(--(INT(Attendance[Start time])=Training_Attendance[[#This Row],[Date]]),0)*IFERROR(--(ISNUMBER(SEARCH(J$1,Attendance[Attendees]))),0)*IFERROR(--(Attendance[Session Type]="Training"),0))>0,"Y","")} | K11: {=IF(SUMPRODUCT(IFERROR(--(INT(Attendance[Start time])=Training_Attendance[[#This Row],[Date]]),0)*IFERROR(--(ISNUMBER(SEARCH(K$1,Attendance[Attendees]))),0)*IFERROR(--(Attendance[Session Type]="Training"),0))>0,"Y","")} | ... AC11: {=IF(SUMPRODUCT(IFERROR(--(INT(Attendance[Start time])=Training_Attendance[[#This Row],[Date]]),0)*IFERROR(--(ISNUMBER(SEARCH(AC$1,Attendance[Attendees]))),0)*IFERROR(--(Attendance[Session Type]="Training"),0))>0,"Y","")} | AD11: =COUNTIF(Training_Attendance[[#This Row],[Alf M]:[Ronnie D]],"Y") -> 0
A12: 46337 | B12: =Training_Attendance[[#This Row],[Date]] -> 46337 | C12: Training | D12: {=IF(SUMPRODUCT(IFERROR(--(INT(Attendance[Start time])=Training_Attendance[[#This Row],[Date]]),0)*IFERROR(--(ISNUMBER(SEARCH(D$1,Attendance[Attendees]))),0)*IFERROR(--(Attendance[Session Type]="Training"),0))>0,"Y","")} | E12: {=IF(SUMPRODUCT(IFERROR(--(INT(Attendance[Start time])=Training_Attendance[[#This Row],[Date]]),0)*IFERROR(--(ISNUMBER(SEARCH(E$1,Attendance[Attendees]))),0)*IFERROR(--(Attendance[Session Type]="Training"),0))>0,"Y","")} | F12: {=IF(SUMPRODUCT(IFERROR(--(INT(Attendance[Start time])=Training_Attendance[[#This Row],[Date]]),0)*IFERROR(--(ISNUMBER(SEARCH(F$1,Attendance[Attendees]))),0)*IFERROR(--(Attendance[Session Type]="Training"),0))>0,"Y","")} | G12: {=IF(SUMPRODUCT(IFERROR(--(INT(Attendance[Start time])=Training_Attendance[[#This Row],[Date]]),0)*IFERROR(--(ISNUMBER(SEARCH(G$1,Attendance[Attendees]))),0)*IFERROR(--(Attendance[Session Type]="Training"),0))>0,"Y","")} | H12: {=IF(SUMPRODUCT(IFERROR(--(INT(Attendance[Start time])=Training_Attendance[[#This Row],[Date]]),0)*IFERROR(--(ISNUMBER(SEARCH(H$1,Attendance[Attendees]))),0)*IFERROR(--(Attendance[Session Type]="Training"),0))>0,"Y","")} | I12: {=IF(SUMPRODUCT(IFERROR(--(INT(Attendance[Start time])=Training_Attendance[[#This Row],[Date]]),0)*IFERROR(--(ISNUMBER(SEARCH(I$1,Attendance[Attendees]))),0)*IFERROR(--(Attendance[Session Type]="Training"),0))>0,"Y","")} | J12: {=IF(SUMPRODUCT(IFERROR(--(INT(Attendance[Start time])=Training_Attendance[[#This Row],[Date]]),0)*IFERROR(--(ISNUMBER(SEARCH(J$1,Attendance[Attendees]))),0)*IFERROR(--(Attendance[Session Type]="Training"),0))>0,"Y","")} | K12: {=IF(SUMPRODUCT(IFERROR(--(INT(Attendance[Start time])=Training_Attendance[[#This Row],[Date]]),0)*IFERROR(--(ISNUMBER(SEARCH(K$1,Attendance[Attendees]))),0)*IFERROR(--(Attendance[Session Type]="Training"),0))>0,"Y","")} | ... AC12: {=IF(SUMPRODUCT(IFERROR(--(INT(Attendance[Start time])=Training_Attendance[[#This Row],[Date]]),0)*IFERROR(--(ISNUMBER(SEARCH(AC$1,Attendance[Attendees]))),0)*IFERROR(--(Attendance[Session Type]="Training"),0))>0,"Y","")} | AD12: =COUNTIF(Training_Attendance[[#This Row],[Alf M]:[Ronnie D]],"Y") -> 0
A13: 46344 | B13: =Training_Attendance[[#This Row],[Date]] -> 46344 | C13: Training | D13: {=IF(SUMPRODUCT(IFERROR(--(INT(Attendance[Start time])=Training_Attendance[[#This Row],[Date]]),0)*IFERROR(--(ISNUMBER(SEARCH(D$1,Attendance[Attendees]))),0)*IFERROR(--(Attendance[Session Type]="Training"),0))>0,"Y","")} | E13: {=IF(SUMPRODUCT(IFERROR(--(INT(Attendance[Start time])=Training_Attendance[[#This Row],[Date]]),0)*IFERROR(--(ISNUMBER(SEARCH(E$1,Attendance[Attendees]))),0)*IFERROR(--(Attendance[Session Type]="Training"),0))>0,"Y","")} | F13: {=IF(SUMPRODUCT(IFERROR(--(INT(Attendance[Start time])=Training_Attendance[[#This Row],[Date]]),0)*IFERROR(--(ISNUMBER(SEARCH(F$1,Attendance[Attendees]))),0)*IFERROR(--(Attendance[Session Type]="Training"),0))>0,"Y","")} | G13: {=IF(SUMPRODUCT(IFERROR(--(INT(Attendance[Start time])=Training_Attendance[[#This Row],[Date]]),0)*IFERROR(--(ISNUMBER(SEARCH(G$1,Attendance[Attendees]))),0)*IFERROR(--(Attendance[Session Type]="Training"),0))>0,"Y","")} | H13: {=IF(SUMPRODUCT(IFERROR(--(INT(Attendance[Start time])=Training_Attendance[[#This Row],[Date]]),0)*IFERROR(--(ISNUMBER(SEARCH(H$1,Attendance[Attendees]))),0)*IFERROR(--(Attendance[Session Type]="Training"),0))>0,"Y","")} | I13: {=IF(SUMPRODUCT(IFERROR(--(INT(Attendance[Start time])=Training_Attendance[[#This Row],[Date]]),0)*IFERROR(--(ISNUMBER(SEARCH(I$1,Attendance[Attendees]))),0)*IFERROR(--(Attendance[Session Type]="Training"),0))>0,"Y","")} | J13: {=IF(SUMPRODUCT(IFERROR(--(INT(Attendance[Start time])=Training_Attendance[[#This Row],[Date]]),0)*IFERROR(--(ISNUMBER(SEARCH(J$1,Attendance[Attendees]))),0)*IFERROR(--(Attendance[Session Type]="Training"),0))>0,"Y","")} | K13: {=IF(SUMPRODUCT(IFERROR(--(INT(Attendance[Start time])=Training_Attendance[[#This Row],[Date]]),0)*IFERROR(--(ISNUMBER(SEARCH(K$1,Attendance[Attendees]))),0)*IFERROR(--(Attendance[Session Type]="Training"),0))>0,"Y","")} | ... AC13: {=IF(SUMPRODUCT(IFERROR(--(INT(Attendance[Start time])=Training_Attendance[[#This Row],[Date]]),0)*IFERROR(--(ISNUMBER(SEARCH(AC$1,Attendance[Attendees]))),0)*IFERROR(--(Attendance[Session Type]="Training"),0))>0,"Y","")} | AD13: =COUNTIF(Training_Attendance[[#This Row],[Alf M]:[Ronnie D]],"Y") -> 0
... A53: 46624 | B53: =Training_Attendance[[#This Row],[Date]] -> 46624 | C53: Training | D53: {=IF(SUMPRODUCT(IFERROR(--(INT(Attendance[Start time])=Training_Attendance[[#This Row],[Date]]),0)*IFERROR(--(ISNUMBER(SEARCH(D$1,Attendance[Attendees]))),0)*IFERROR(--(Attendance[Session Type]="Training"),0))>0,"Y","")} | E53: {=IF(SUMPRODUCT(IFERROR(--(INT(Attendance[Start time])=Training_Attendance[[#This Row],[Date]]),0)*IFERROR(--(ISNUMBER(SEARCH(E$1,Attendance[Attendees]))),0)*IFERROR(--(Attendance[Session Type]="Training"),0))>0,"Y","")} | F53: {=IF(SUMPRODUCT(IFERROR(--(INT(Attendance[Start time])=Training_Attendance[[#This Row],[Date]]),0)*IFERROR(--(ISNUMBER(SEARCH(F$1,Attendance[Attendees]))),0)*IFERROR(--(Attendance[Session Type]="Training"),0))>0,"Y","")} | G53: {=IF(SUMPRODUCT(IFERROR(--(INT(Attendance[Start time])=Training_Attendance[[#This Row],[Date]]),0)*IFERROR(--(ISNUMBER(SEARCH(G$1,Attendance[Attendees]))),0)*IFERROR(--(Attendance[Session Type]="Training"),0))>0,"Y","")} | H53: {=IF(SUMPRODUCT(IFERROR(--(INT(Attendance[Start time])=Training_Attendance[[#This Row],[Date]]),0)*IFERROR(--(ISNUMBER(SEARCH(H$1,Attendance[Attendees]))),0)*IFERROR(--(Attendance[Session Type]="Training"),0))>0,"Y","")} | I53: {=IF(SUMPRODUCT(IFERROR(--(INT(Attendance[Start time])=Training_Attendance[[#This Row],[Date]]),0)*IFERROR(--(ISNUMBER(SEARCH(I$1,Attendance[Attendees]))),0)*IFERROR(--(Attendance[Session Type]="Training"),0))>0,"Y","")} | J53: {=IF(SUMPRODUCT(IFERROR(--(INT(Attendance[Start time])=Training_Attendance[[#This Row],[Date]]),0)*IFERROR(--(ISNUMBER(SEARCH(J$1,Attendance[Attendees]))),0)*IFERROR(--(Attendance[Session Type]="Training"),0))>0,"Y","")} | K53: {=IF(SUMPRODUCT(IFERROR(--(INT(Attendance[Start time])=Training_Attendance[[#This Row],[Date]]),0)*IFERROR(--(ISNUMBER(SEARCH(K$1,Attendance[Attendees]))),0)*IFERROR(--(Attendance[Session Type]="Training"),0))>0,"Y","")} | ... AC53: {=IF(SUMPRODUCT(IFERROR(--(INT(Attendance[Start time])=Training_Attendance[[#This Row],[Date]]),0)*IFERROR(--(ISNUMBER(SEARCH(AC$1,Attendance[Attendees]))),0)*IFERROR(--(Attendance[Session Type]="Training"),0))>0,"Y","")} | AD53: =COUNTIF(Training_Attendance[[#This Row],[Alf M]:[Ronnie D]],"Y") -> 0
C54: Total Trained | D54: =COUNTIF(D2:D53, "Y") -> 1 | E54: =COUNTIF(E2:E53, "Y") -> 0 | F54: =COUNTIF(F2:F53, "Y") -> 0 | G54: =COUNTIF(G2:G53, "Y") -> 0 | H54: =COUNTIF(H2:H53, "Y") -> 0 | I54: =COUNTIF(I2:I53, "Y") -> 1 | J54: =COUNTIF(J2:J53, "Y") -> 0 | K54: =COUNTIF(K2:K53, "Y") -> 0 | ... AC54: =COUNTIF(AC2:AC53, "Y") -> 0 | AD54: =SUBTOTAL(109,Training_Attendance[COUNT]) -> 5
